#VRML_SIM R2025a utf8

EXTERNPROTO "https://raw.githubusercontent.com/cyberbotics/webots/R2025a/projects/objects/backgrounds/protos/TexturedBackground.proto"
EXTERNPROTO "https://raw.githubusercontent.com/cyberbotics/webots/R2025a/projects/objects/backgrounds/protos/TexturedBackgroundLight.proto"
EXTERNPROTO "https://raw.githubusercontent.com/cyberbotics/webots/R2025a/projects/objects/factory/containers/protos/WoodenBox.proto"
EXTERNPROTO "https://raw.githubusercontent.com/cyberbotics/webots/R2025a/projects/objects/floors/protos/Floor.proto"

WorldInfo {
  basicTimeStep 16
  contactProperties [
    ContactProperties {
      coulombFriction [
        0.5
      ]
    }
  ]
}
Viewpoint {
  orientation 0.469809136984034 -0.34617941191959617 -0.812058612151438 4.220024946795043
  position 0.28145788121712956 -0.5795002561309667 1.4753448902234159
}
TexturedBackground {
}
TexturedBackgroundLight {
}
Floor {
  translation 0 0 0.05
  size 1 1
  tileSize 0.25 0.25
}
WoodenBox {
  translation -0.258311 0.262759 0.1
  name "wooden box(2)"
  size 0.1 0.1 0.1
}
WoodenBox {
  translation -0.159831 -0.225984 0.1
  size 0.1 0.1 0.1
}
WoodenBox {
  translation 0.275095 0.0521046 0.1
  name "wooden box(1)"
  size 0.1 0.1 0.1
}
Solid {
  translation 0.504893 0.00628611 0.09
  children [
    DEF WALL Shape {
      appearance PBRAppearance {
        baseColor 0.101961 0.372549 0.705882
        roughness 1
        metalness 0
      }
      geometry Box {
        size 0.02 1.1 0.1
      }
    }
  ]
  name "wall"
  boundingObject USE WALL
}
Solid {
  translation -0.00397925 0.516216 0.09
  rotation 0 0 1 1.5708
  children [
    USE WALL
  ]
  name "wall(1)"
  boundingObject USE WALL
}
Solid {
  translation -0.00718594 -0.496021 0.09
  rotation 0 0 1 1.5708
  children [
    USE WALL
  ]
  name "wall(3)"
  boundingObject USE WALL
}
Solid {
  translation -0.510305 0.0122146 0.09
  children [
    USE WALL
  ]
  name "wall(2)"
  boundingObject USE WALL
}
Robot {
  translation -0.186308 -0.0101411 0.0898601
  rotation -0.0041176708114883855 -0.9999601045964922 -0.007926790173882911 0.0009838277111190894
  children [
    DistanceSensor {
      translation 0.1 0.03 0
      rotation 0 0 1 0.3
      children [
        DEF DT_SENSOR Shape {
          appearance PBRAppearance {
            roughness 1
            metalness 0
          }
          geometry Box {
            size 0.01 0.01 0.01
          }
        }
      ]
      name "ds_left"
      boundingObject USE DT_SENSOR
    }
    DistanceSensor {
      translation 0.1 -0.03 0
      rotation 0 0 1 -0.3
      children [
        USE DT_SENSOR
      ]
      name "ds_right"
      boundingObject USE DT_SENSOR
    }
    DEF ROBOT Shape {
      appearance PBRAppearance {
        baseColor 0.964706 0.380392 0.317647
        roughness 1
        metalness 0
      }
      geometry Box {
        size 0.2 0.1 0.05
      }
    }
    HingeJoint {
      jointParameters HingeJointParameters {
        position 18.784542595087636
        axis 0 1 0
        anchor -0.05 0.06 0
      }
      device [
        RotationalMotor {
          name "wheel1"
        }
      ]
      endPoint Solid {
        translation -0.05 0.06 0
        rotation -0.4911078718960778 0.6162050475565635 -0.6157145422413856 4.055240252022877
        children [
          Shape {
            appearance PBRAppearance {
              baseColor 0.14902 0.635294 0.411765
              roughness 1
              metalness 0
            }
            geometry Cylinder {
              height 0.02
              radius 0.04
            }
          }
        ]
        name "wheelsolid1"
        boundingObject DEF WHEEL Shape {
          appearance PBRAppearance {
            baseColor 0.14902 0.635294 0.411765
            roughness 1
            metalness 0
          }
          geometry Cylinder {
            height 0.02
            radius 0.04
          }
        }
        physics DEF WHEEL_PH Physics {
        }
      }
    }
    HingeJoint {
      jointParameters HingeJointParameters {
        position 18.78239449080092
        axis 0 1 0
        anchor -0.05 -0.06 0
      }
      device [
        RotationalMotor {
          name "wheel2"
        }
      ]
      endPoint Solid {
        translation -0.05 -0.06 0
        rotation -0.9988724977017648 0.03358219801546383 -0.03355546619387474 4.7120571706410335
        children [
          DEF WHEEL Shape {
            appearance PBRAppearance {
              baseColor 0.14902 0.635294 0.411765
              roughness 1
              metalness 0
            }
            geometry Cylinder {
              height 0.02
              radius 0.04
            }
          }
        ]
        name "wheelsolid2"
        boundingObject DEF WHEEL Shape {
          appearance PBRAppearance {
            baseColor 0.14902 0.635294 0.411765
            roughness 1
            metalness 0
          }
          geometry Cylinder {
            height 0.02
            radius 0.04
          }
        }
        physics DEF WHEEL_PH Physics {
        }
      }
    }
    HingeJoint {
      jointParameters HingeJointParameters {
        position 18.782394483970826
        axis 0 1 0
        anchor 0.05 -0.06 0
      }
      device [
        RotationalMotor {
          name "wheel3"
        }
      ]
      endPoint Solid {
        translation 0.049999996249205786 -0.06000000010365339 5.76373500820372e-08
        rotation -0.9988724974781432 0.03358220134665395 -0.033555469516752826 4.7120571705858945
        children [
          DEF WHEEL Shape {
            appearance PBRAppearance {
              baseColor 0.14902 0.635294 0.411765
              roughness 1
              metalness 0
            }
            geometry Cylinder {
              height 0.02
              radius 0.04
            }
          }
        ]
        name "wheelsolid3"
        boundingObject DEF WHEEL Shape {
          appearance PBRAppearance {
            baseColor 0.14902 0.635294 0.411765
            roughness 1
            metalness 0
          }
          geometry Cylinder {
            height 0.02
            radius 0.04
          }
        }
        physics DEF WHEEL_PH Physics {
        }
      }
    }
    HingeJoint {
      jointParameters HingeJointParameters {
        position 18.782394585728564
        axis 0 1 0
        anchor 0.05 0.06 0
      }
      device [
        RotationalMotor {
          name "wheel4"
        }
      ]
      endPoint Solid {
        translation 0.05 0.06 0
        rotation -0.49110785212581903 0.616205055441164 -0.6157145501197099 4.05524022015035
        children [
          DEF WHEEL Shape {
            appearance PBRAppearance {
              baseColor 0.14902 0.635294 0.411765
              roughness 1
              metalness 0
            }
            geometry Cylinder {
              height 0.02
              radius 0.04
            }
          }
        ]
        name "wheelsolid4"
        boundingObject DEF WHEEL Shape {
          appearance PBRAppearance {
            baseColor 0.14902 0.635294 0.411765
            roughness 1
            metalness 0
          }
          geometry Cylinder {
            height 0.02
            radius 0.04
          }
        }
        physics DEF WHEEL_PH Physics {
        }
      }
    }
  ]
  boundingObject USE ROBOT
  physics Physics {
  }
  controller "four_wheeled_robot_controller"
}
